Workbook
Name mileage_data: OFFSET('Charging>Miles'!$A$1, 0, 0, COUNTA('Charging>Miles'!$A:$A), 4)
Name PivotMileage: OFFSET('Charging>Miles'!$G$5, 0, 0, COUNTA('Charging>Miles'!$F$5:$F$100)-1, 1)
Name sample: 'Charging>Miles'!$C$14:$C$17
Name VehicleList: OFFSET(Vehicle_Input!$A$2, 0, 0, COUNTA(Vehicle_Input!$A:$A)-1, 1)

Sheet Vehicle_Input
A1: Vehicle | B1: New Car Price | C1: Down Payment + Trade IN | D1: Tax Credit | E1: Taxes and Fees | F1: Loan Amount | G1: Loan Term | H1: APR | I1: Loan Term (Months) | J1: Starting Mileage | K1: Misc. Costs | L1: Tires | M1: CarWashes
A2: Model Y | B2: 40000 | C2: 5000 | D2: 7500 | E2: 3000 | F2: 35000 | H2: 0.04 | I2: 60
A3: Mach E
A4: Lexus ES 300H | B4: 32000 | C4: 0 | F4: 32000 | H4: 0.14 | I4: 72 | J4: 26000

Sheet Outputs
A1: Loan Terms
A3: Vehicle: | B3: Lexus ES 300H
B4: Dollar Amount ($)
A6: New Car Price | B6: =_xlfn.XLOOKUP($B$3, Vehicle_Input!$A$2:$A$100, Vehicle_Input!B$2:B$100, "Not Found") -> 32000
A7: Down Payment + Trade IN | B7: =_xlfn.XLOOKUP($B$3, Vehicle_Input!$A$2:$A$100, Vehicle_Input!C$2:C$100, "Not Found") -> 0
A8: Starting Mileage | B8: =_xlfn.XLOOKUP($B$3, Vehicle_Input!$A$2:$A$100, Vehicle_Input!J$2:J$100, "Not Found") -> 26000
A9: Tax Credit | B9: =_xlfn.XLOOKUP($B$3, Vehicle_Input!$A$2:$A$100, Vehicle_Input!D$2:D$100, "Not Found") -> 0
A10: Taxes and Fees | B10: =_xlfn.XLOOKUP($B$3, Vehicle_Input!$A$2:$A$100, Vehicle_Input!E$2:E$100, "Not Found") -> 0
A11: Loan Amount | B11: =_xlfn.XLOOKUP($B$3, Vehicle_Input!$A$2:$A$100, Vehicle_Input!F$2:F$100, "Not Found") -> 32000
A12: APR | B12: =_xlfn.XLOOKUP($B$3, Vehicle_Input!$A$2:$A$100, Vehicle_Input!H$2:H$100, "Not Found") -> 0.14
A13: Loan Term (months)60 | B13: =_xlfn.XLOOKUP($B$3, Vehicle_Input!$A$2:$A$100, Vehicle_Input!I$2:I$100, "Not Found") -> 72
A14: Payment Amount | B14: =-PMT((B12/12), B13, (B6-B7)) -> 659.38366
A15: Total Payments | B15: =B14 * B13 -> 47475.624
A16: Total Interest Paid at end of Loan | B16: =SUM(OFFSET(Amortization!$F$2, 0, 0, COUNT(Amortization!$F$2:$F$100), 1)) -> 7997.2852
A18: Interest Paid:
A19: 1st year | B19: =SUM(OFFSET(Amortization!$F$2, 0, 0, 12, 1)) -> 4024.9629
A20: 2nd year | B20: =SUM(OFFSET(Amortization!$F$2, 12, 0, 12, 1)) -> 2839.5657
A21: 3rd year | B21: =SUM(OFFSET(Amortization!$F$2, 24, 0, 12, 1)) -> 1496.6181
A24: Trade In Value = Principle Paid
A25: Principle Paid Deadline (months) | C25: <<<<<
A26: Avg Monthly Payment Required to Meet Deadline
A34: Expected Trade In Value after x year(s) | B34: 2.5
A35: Trade-In Value | B35: =B6 * (1 - MIN(1, (0.2 + (0.1 * (B34 - 1)) + (J6 * 52 * B34 / 150000)))) -> 20800
A36: Weekly Breakeven
A37: Mileage/Year
A38: ="Value after " & (ROW($A$35) - 19) & " year with ~" & TEXT('Charging>Miles'!$J$6 * 52 * (ROW($A$35) - 19), "#,##0") & " miles" -> Value after 16 year with ~490,218 miles
A39: ="Value after 2 years with ~" & TEXT('Charging>Miles'!$J$6 * 52 * 2, "#,##0") & " miles" -> Value after 2 years with ~61,277 miles
A40: ="Value after 2.5 years with ~" & TEXT('Charging>Miles'!$J$6 * 52 * 2.5, "#,##0") & " miles" -> Value after 2.5 years with ~76,597 miles
A42: Savings
A43: Monthly Avg Savings
A44: Reserves Balance | B44: 2000
A48: Costs | C48: -1
B49: Weekly Amount ($) | C49: Annualized | D49: Monthly
A50: Weekly Average | B50: 1300 | C50: =B50*52 -> 67600 | D50: =B50*4 -> 5200
A51: Weekly Energy Costs | B51: -45 | C51: 2340 | D51: 180
A52: Weekly Car Wash | B52: -10 | C52: 468 | D52: =B52*4 -> -40
A53: Tires (~70 weeks) | B53: =C53/70 -> -15.714286 | C53: -1100 | D53: =C53/12 -> -91.666667
A57: Note: annual costs are divided by 52
A61: Depreciation
B62: Dollar Amount ($) | C62: Annualized | D62: Monthly
...

Sheet Amortization
A1: Payment Number | B1: Payment Date | C1: Beginning Balance | D1: Min Payment Amount | E1: Excess Min Payment Amount | F1: Interest Paid | G1: Principal Paid | H1: Equity | I1: Ending Balance | J1: Trade Value-Equity
A2: =IF(ROW(A2)-ROW($A$1) <= $M$5, ROW(A2)-ROW($A$1), "") -> 1 | B2: =$M$2 -> 45658 | C2: =IF(A2<>"", Outputs!B11, "") -> 32000 | D2: =IF(A2<>"", $M$6, "") -> 659.38366 | F2: =IF(A2<>"", C2 * ($M$4 / 12), "") -> 373.33333 | G2: =IF(A2<>"", D2 - F2+E2, "") -> 286.05033 | H2: =G2 -> 286.05033 | I2: =IF(A2<>"", C2 - G2, "") -> 31713.95 | J2: =IF(A2<>"",Depreciation!F4,"") -> 31119.678 | L2: Starting Date | M2: 45658
A3: =IF(ROW(A3)-ROW($A$1) <= $M$5, ROW(A3)-ROW($A$1), "") -> 2 | B3: =IF(A3<>"", EDATE(B2,1), "") -> 45689 | C3: =IF(A3<>"", I2, "") -> 31713.95 | D3: =IF(A3<>"", $M$6, "") -> 659.38366 | E3: 340 | F3: =IF(A3<>"", C3 * ($M$4 / 12), "") -> 369.99608 | G3: =IF(A3<>"", D3 - F3+E3, "") -> 629.38758 | H3: =IF(A3<>"",H2+G3,"") -> 915.43791 | I3: =IF(A3<>"", C3 - G3, "") -> 31084.562 | J3: =IF(A3<>"",Depreciation!F5,"") -> 30239.356 | L3: Loan Amount | M3: =Outputs!B6-Outputs!B7 -> 32000
A4: =IF(ROW(A4)-ROW($A$1) <= $M$5, ROW(A4)-ROW($A$1), "") -> 3 | B4: =IF(A4<>"", EDATE(B3,1), "") -> 45717 | C4: =IF(A4<>"", I3, "") -> 31084.562 | D4: =IF(A4<>"", $M$6, "") -> 659.38366 | E4: 340 | F4: =IF(A4<>"", C4 * ($M$4 / 12), "") -> 362.65322 | G4: =IF(A4<>"", D4 - F4+E4, "") -> 636.73044 | H4: =IF(A4<>"",H3+G4,"") -> 1552.1684 | I4: =IF(A4<>"", C4 - G4, "") -> 30447.832 | J4: =IF(A4<>"",Depreciation!F6,"") -> 29359.034 | L4: Annual Interest Rate | M4: =Outputs!B12 -> 0.14
A5: =IF(ROW(A5)-ROW($A$1) <= $M$5, ROW(A5)-ROW($A$1), "") -> 4 | B5: =IF(A5<>"", EDATE(B4,1), "") -> 45748 | C5: =IF(A5<>"", I4, "") -> 30447.832 | D5: =IF(A5<>"", $M$6, "") -> 659.38366 | E5: 340 | F5: =IF(A5<>"", C5 * ($M$4 / 12), "") -> 355.2247 | G5: =IF(A5<>"", D5 - F5+E5, "") -> 644.15896 | H5: =IF(A5<>"",H4+G5,"") -> 2196.3273 | I5: =IF(A5<>"", C5 - G5, "") -> 29803.673 | J5: =IF(A5<>"",Depreciation!F7,"") -> 28478.712 | L5: Loan Term (Months) | M5: 60
A6: =IF(ROW(A6)-ROW($A$1) <= $M$5, ROW(A6)-ROW($A$1), "") -> 5 | B6: =IF(A6<>"", EDATE(B5,1), "") -> 45778 | C6: =IF(A6<>"", I5, "") -> 29803.673 | D6: =IF(A6<>"", $M$6, "") -> 659.38366 | E6: 340 | F6: =IF(A6<>"", C6 * ($M$4 / 12), "") -> 347.70951 | G6: =IF(A6<>"", D6 - F6+E6, "") -> 651.67415 | H6: =IF(A6<>"",H5+G6,"") -> 2848.0015 | I6: =IF(A6<>"", C6 - G6, "") -> 29151.999 | J6: =IF(A6<>"",Depreciation!F8,"") -> 27598.39 | L6: Monthly Min Payment | M6: =Outputs!B14 -> 659.38366
A7: =IF(ROW(A7)-ROW($A$1) <= $M$5, ROW(A7)-ROW($A$1), "") -> 6 | B7: =IF(A7<>"", EDATE(B6,1), "") -> 45809 | C7: =IF(A7<>"", I6, "") -> 29151.999 | D7: =IF(A7<>"", $M$6, "") -> 659.38366 | E7: 340 | F7: =IF(A7<>"", C7 * ($M$4 / 12), "") -> 340.10665 | G7: =IF(A7<>"", D7 - F7+E7, "") -> 659.27701 | H7: =IF(A7<>"",H6+G7,"") -> 3507.2785 | I7: =IF(A7<>"", C7 - G7, "") -> 28492.722 | J7: =IF(A7<>"",Depreciation!F9,"") -> 26718.068 | L7: Monthly Avg Payment | M7: 1000
A8: =IF(ROW(A8)-ROW($A$1) <= $M$5, ROW(A8)-ROW($A$1), "") -> 7 | B8: =IF(A8<>"", EDATE(B7,1), "") -> 45839 | C8: =IF(A8<>"", I7, "") -> 28492.722 | D8: =IF(A8<>"", $M$6, "") -> 659.38366 | E8: 340 | F8: =IF(A8<>"", C8 * ($M$4 / 12), "") -> 332.41508 | G8: =IF(A8<>"", D8 - F8+E8, "") -> 666.96858 | H8: =IF(A8<>"",H7+G8,"") -> 4174.2471 | I8: =IF(A8<>"", C8 - G8, "") -> 27825.753 | J8: =IF(A8<>"",Depreciation!F10,"") -> 25837.746
A9: =IF(ROW(A9)-ROW($A$1) <= $M$5, ROW(A9)-ROW($A$1), "") -> 8 | B9: =IF(A9<>"", EDATE(B8,1), "") -> 45870 | C9: =IF(A9<>"", I8, "") -> 27825.753 | D9: =IF(A9<>"", $M$6, "") -> 659.38366 | E9: 340 | F9: =IF(A9<>"", C9 * ($M$4 / 12), "") -> 324.63378 | G9: =IF(A9<>"", D9 - F9+E9, "") -> 674.74988 | H9: =IF(A9<>"",H8+G9,"") -> 4848.9969 | I9: =IF(A9<>"", C9 - G9, "") -> 27151.003 | J9: =IF(A9<>"",Depreciation!F11,"") -> 24957.424
A10: =IF(ROW(A10)-ROW($A$1) <= $M$5, ROW(A10)-ROW($A$1), "") -> 9 | B10: =IF(A10<>"", EDATE(B9,1), "") -> 45901 | C10: =IF(A10<>"", I9, "") -> 27151.003 | D10: =IF(A10<>"", $M$6, "") -> 659.38366 | E10: 340 | F10: =IF(A10<>"", C10 * ($M$4 / 12), "") -> 316.7617 | G10: =IF(A10<>"", D10 - F10+E10, "") -> 682.62196 | H10: =IF(A10<>"",H9+G10,"") -> 5531.6189 | I10: =IF(A10<>"", C10 - G10, "") -> 26468.381 | J10: =IF(A10<>"",Depreciation!F12,"") -> 24077.102 | L10: APR List | N10: Loan Term
A11: =IF(ROW(A11)-ROW($A$1) <= $M$5, ROW(A11)-ROW($A$1), "") -> 10 | B11: =IF(A11<>"", EDATE(B10,1), "") -> 45931 | C11: =IF(A11<>"", I10, "") -> 26468.381 | D11: =IF(A11<>"", $M$6, "") -> 659.38366 | E11: 340 | F11: =IF(A11<>"", C11 * ($M$4 / 12), "") -> 308.79778 | G11: =IF(A11<>"", D11 - F11+E11, "") -> 690.58588 | H11: =IF(A11<>"",H10+G11,"") -> 6222.2048 | I11: =IF(A11<>"", C11 - G11, "") -> 25777.795 | J11: =IF(A11<>"",Depreciation!F13,"") -> 23196.78 | L11: 0 | N11: 24
A12: =IF(ROW(A12)-ROW($A$1) <= $M$5, ROW(A12)-ROW($A$1), "") -> 11 | B12: =IF(A12<>"", EDATE(B11,1), "") -> 45962 | C12: =IF(A12<>"", I11, "") -> 25777.795 | D12: =IF(A12<>"", $M$6, "") -> 659.38366 | E12: 340 | F12: =IF(A12<>"", C12 * ($M$4 / 12), "") -> 300.74094 | G12: =IF(A12<>"", D12 - F12+E12, "") -> 698.64272 | H12: =IF(A12<>"",H11+G12,"") -> 6920.8475 | I12: =IF(A12<>"", C12 - G12, "") -> 25079.153 | J12: =IF(A12<>"",Depreciation!F14,"") -> 22316.458 | L12: 0.01 | N12: 36
A13: =IF(ROW(A13)-ROW($A$1) <= $M$5, ROW(A13)-ROW($A$1), "") -> 12 | B13: =IF(A13<>"", EDATE(B12,1), "") -> 45992 | C13: =IF(A13<>"", I12, "") -> 25079.153 | D13: =IF(A13<>"", $M$6, "") -> 659.38366 | E13: 340 | F13: =IF(A13<>"", C13 * ($M$4 / 12), "") -> 292.59011 | G13: =IF(A13<>"", D13 - F13+E13, "") -> 706.79355 | H13: =IF(A13<>"",H12+G13,"") -> 7627.641 | I13: =IF(A13<>"", C13 - G13, "") -> 24372.359 | J13: =IF(A13<>"",Depreciation!F15,"") -> 21569.469 | L13: 0.02 | N13: 48
A14: =IF(ROW(A14)-ROW($A$1) <= $M$5, ROW(A14)-ROW($A$1), "") -> 13 | B14: =IF(A14<>"", EDATE(B13,1), "") -> 46023 | C14: =IF(A14<>"", I13, "") -> 24372.359 | D14: =IF(A14<>"", $M$6, "") -> 659.38366 | E14: 340 | F14: =IF(A14<>"", C14 * ($M$4 / 12), "") -> 284.34419 | G14: =IF(A14<>"", D14 - F14+E14, "") -> 715.03948 | H14: =IF(A14<>"",H13+G14,"") -> 8342.6805 | I14: =IF(A14<>"", C14 - G14, "") -> 23657.319 | J14: =IF(A14<>"",Depreciation!F16,"") -> 20822.481 | L14: 0.03 | N14: 60
A15: =IF(ROW(A15)-ROW($A$1) <= $M$5, ROW(A15)-ROW($A$1), "") -> 14 | B15: =IF(A15<>"", EDATE(B14,1), "") -> 46054 | C15: =IF(A15<>"", I14, "") -> 23657.319 | D15: =IF(A15<>"", $M$6, "") -> 659.38366 | E15: 340 | F15: =IF(A15<>"", C15 * ($M$4 / 12), "") -> 276.00206 | G15: =IF(A15<>"", D15 - F15+E15, "") -> 723.3816 | H15: =IF(A15<>"",H14+G15,"") -> 9066.0621 | I15: =IF(A15<>"", C15 - G15, "") -> 22933.938 | J15: =IF(A15<>"",Depreciation!F17,"") -> 20075.492 | L15: 0.04 | N15: 72
A16: =IF(ROW(A16)-ROW($A$1) <= $M$5, ROW(A16)-ROW($A$1), "") -> 15 | B16: =IF(A16<>"", EDATE(B15,1), "") -> 46082 | C16: =IF(A16<>"", I15, "") -> 22933.938 | D16: =IF(A16<>"", $M$6, "") -> 659.38366 | E16: 340 | F16: =IF(A16<>"", C16 * ($M$4 / 12), "") -> 267.56261 | G16: =IF(A16<>"", D16 - F16+E16, "") -> 731.82105 | H16: =IF(A16<>"",H15+G16,"") -> 9797.8832 | I16: =IF(A16<>"", C16 - G16, "") -> 22202.117 | J16: =IF(A16<>"",Depreciation!F18,"") -> 19328.503 | L16: 0.05
A17: =IF(ROW(A17)-ROW($A$1) <= $M$5, ROW(A17)-ROW($A$1), "") -> 16 | B17: =IF(A17<>"", EDATE(B16,1), "") -> 46113 | C17: =IF(A17<>"", I16, "") -> 22202.117 | D17: =IF(A17<>"", $M$6, "") -> 659.38366 | E17: 340 | F17: =IF(A17<>"", C17 * ($M$4 / 12), "") -> 259.0247 | G17: =IF(A17<>"", D17 - F17+E17, "") -> 740.35897 | H17: =IF(A17<>"",H16+G17,"") -> 10538.242 | I17: =IF(A17<>"", C17 - G17, "") -> 21461.758 | J17: =IF(A17<>"",Depreciation!F19,"") -> 18581.514 | L17: 0.06
A18: =IF(ROW(A18)-ROW($A$1) <= $M$5, ROW(A18)-ROW($A$1), "") -> 17 | B18: =IF(A18<>"", EDATE(B17,1), "") -> 46143 | C18: =IF(A18<>"", I17, "") -> 21461.758 | D18: =IF(A18<>"", $M$6, "") -> 659.38366 | E18: 340 | F18: =IF(A18<>"", C18 * ($M$4 / 12), "") -> 250.38717 | G18: =IF(A18<>"", D18 - F18+E18, "") -> 748.99649 | H18: =IF(A18<>"",H17+G18,"") -> 11287.239 | I18: =IF(A18<>"", C18 - G18, "") -> 20712.761 | J18: =IF(A18<>"",Depreciation!F20,"") -> 17834.526 | L18: 0.07
A19: =IF(ROW(A19)-ROW($A$1) <= $M$5, ROW(A19)-ROW($A$1), "") -> 18 | B19: =IF(A19<>"", EDATE(B18,1), "") -> 46174 | C19: =IF(A19<>"", I18, "") -> 20712.761 | D19: =IF(A19<>"", $M$6, "") -> 659.38366 | E19: 340 | F19: =IF(A19<>"", C19 * ($M$4 / 12), "") -> 241.64888 | G19: =IF(A19<>"", D19 - F19+E19, "") -> 757.73478 | H19: =IF(A19<>"",H18+G19,"") -> 12044.973 | I19: =IF(A19<>"", C19 - G19, "") -> 19955.027 | J19: =IF(A19<>"",Depreciation!F21,"") -> 17087.537 | L19: 0.08
A20: =IF(ROW(A20)-ROW($A$1) <= $M$5, ROW(A20)-ROW($A$1), "") -> 19 | B20: =IF(A20<>"", EDATE(B19,1), "") -> 46204 | C20: =IF(A20<>"", I19, "") -> 19955.027 | D20: =IF(A20<>"", $M$6, "") -> 659.38366 | E20: 340 | F20: =IF(A20<>"", C20 * ($M$4 / 12), "") -> 232.80864 | G20: =IF(A20<>"", D20 - F20+E20, "") -> 766.57502 | H20: =IF(A20<>"",H19+G20,"") -> 12811.548 | I20: =IF(A20<>"", C20 - G20, "") -> 19188.452 | J20: =IF(A20<>"",Depreciation!F22,"") -> 16340.548 | L20: 0.09
A21: =IF(ROW(A21)-ROW($A$1) <= $M$5, ROW(A21)-ROW($A$1), "") -> 20 | B21: =IF(A21<>"", EDATE(B20,1), "") -> 46235 | C21: =IF(A21<>"", I20, "") -> 19188.452 | D21: =IF(A21<>"", $M$6, "") -> 659.38366 | E21: 340 | F21: =IF(A21<>"", C21 * ($M$4 / 12), "") -> 223.86527 | G21: =IF(A21<>"", D21 - F21+E21, "") -> 775.5184 | H21: =IF(A21<>"",H20+G21,"") -> 13587.067 | I21: =IF(A21<>"", C21 - G21, "") -> 18412.933 | J21: =IF(A21<>"",Depreciation!F23,"") -> 15593.56 | L21: 0.1
A22: =IF(ROW(A22)-ROW($A$1) <= $M$5, ROW(A22)-ROW($A$1), "") -> 21 | B22: =IF(A22<>"", EDATE(B21,1), "") -> 46266 | C22: =IF(A22<>"", I21, "") -> 18412.933 | D22: =IF(A22<>"", $M$6, "") -> 659.38366 | E22: 340 | F22: =IF(A22<>"", C22 * ($M$4 / 12), "") -> 214.81755 | G22: =IF(A22<>"", D22 - F22+E22, "") -> 784.56611 | H22: =IF(A22<>"",H21+G22,"") -> 14371.633 | I22: =IF(A22<>"", C22 - G22, "") -> 17628.367 | J22: =IF(A22<>"",Depreciation!F24,"") -> 14846.571 | L22: 0.14
A23: =IF(ROW(A23)-ROW($A$1) <= $M$5, ROW(A23)-ROW($A$1), "") -> 22 | B23: =IF(A23<>"", EDATE(B22,1), "") -> 46296 | C23: =IF(A23<>"", I22, "") -> 17628.367 | D23: =IF(A23<>"", $M$6, "") -> 659.38366 | E23: 340 | F23: =IF(A23<>"", C23 * ($M$4 / 12), "") -> 205.66428 | G23: =IF(A23<>"", D23 - F23+E23, "") -> 793.71938 | H23: =IF(A23<>"",H22+G23,"") -> 15165.352 | I23: =IF(A23<>"", C23 - G23, "") -> 16834.648 | J23: =IF(A23<>"",Depreciation!F25,"") -> 14099.582
A24: =IF(ROW(A24)-ROW($A$1) <= $M$5, ROW(A24)-ROW($A$1), "") -> 23 | B24: =IF(A24<>"", EDATE(B23,1), "") -> 46327 | C24: =IF(A24<>"", I23, "") -> 16834.648 | D24: =IF(A24<>"", $M$6, "") -> 659.38366 | E24: 340 | F24: =IF(A24<>"", C24 * ($M$4 / 12), "") -> 196.40422 | G24: =IF(A24<>"", D24 - F24+E24, "") -> 802.97944 | H24: =IF(A24<>"",H23+G24,"") -> 15968.332 | I24: =IF(A24<>"", C24 - G24, "") -> 16031.668 | J24: =IF(A24<>"",Depreciation!F26,"") -> 13352.594
A25: =IF(ROW(A25)-ROW($A$1) <= $M$5, ROW(A25)-ROW($A$1), "") -> 24 | B25: =IF(A25<>"", EDATE(B24,1), "") -> 46357 | C25: =IF(A25<>"", I24, "") -> 16031.668 | D25: =IF(A25<>"", $M$6, "") -> 659.38366 | E25: 340 | F25: =IF(A25<>"", C25 * ($M$4 / 12), "") -> 187.03613 | G25: =IF(A25<>"", D25 - F25+E25, "") -> 812.34753 | H25: =IF(A25<>"",H24+G25,"") -> 16780.679 | I25: =IF(A25<>"", C25 - G25, "") -> 15219.321 | J25: =IF(A25<>"",Depreciation!F27,"") -> 12738.938
A26: =IF(ROW(A26)-ROW($A$1) <= $M$5, ROW(A26)-ROW($A$1), "") -> 25 | B26: =IF(A26<>"", EDATE(B25,1), "") -> 46388 | C26: =IF(A26<>"", I25, "") -> 15219.321 | D26: =IF(A26<>"", $M$6, "") -> 659.38366 | E26: 340 | F26: =IF(A26<>"", C26 * ($M$4 / 12), "") -> 177.55874 | G26: =IF(A26<>"", D26 - F26+E26, "") -> 821.82492 | H26: =IF(A26<>"",H25+G26,"") -> 17602.504 | I26: =IF(A26<>"", C26 - G26, "") -> 14397.496 | J26: =IF(A26<>"",Depreciation!F28,"") -> 12125.283
A27: =IF(ROW(A27)-ROW($A$1) <= $M$5, ROW(A27)-ROW($A$1), "") -> 26 | B27: =IF(A27<>"", EDATE(B26,1), "") -> 46419 | C27: =IF(A27<>"", I26, "") -> 14397.496 | D27: =IF(A27<>"", $M$6, "") -> 659.38366 | E27: 340 | F27: =IF(A27<>"", C27 * ($M$4 / 12), "") -> 167.97078 | G27: =IF(A27<>"", D27 - F27+E27, "") -> 831.41288 | H27: =IF(A27<>"",H26+G27,"") -> 18433.917 | I27: =IF(A27<>"", C27 - G27, "") -> 13566.083 | J27: =IF(A27<>"",Depreciation!F29,"") -> 11511.628
A28: =IF(ROW(A28)-ROW($A$1) <= $M$5, ROW(A28)-ROW($A$1), "") -> 27 | B28: =IF(A28<>"", EDATE(B27,1), "") -> 46447 | C28: =IF(A28<>"", I27, "") -> 13566.083 | D28: =IF(A28<>"", $M$6, "") -> 659.38366 | E28: 340 | F28: =IF(A28<>"", C28 * ($M$4 / 12), "") -> 158.27097 | G28: =IF(A28<>"", D28 - F28+E28, "") -> 841.1127 | H28: =IF(A28<>"",H27+G28,"") -> 19275.03 | I28: =IF(A28<>"", C28 - G28, "") -> 12724.97 | J28: =IF(A28<>"",Depreciation!F30,"") -> 10897.972
A29: =IF(ROW(A29)-ROW($A$1) <= $M$5, ROW(A29)-ROW($A$1), "") -> 28 | B29: =IF(A29<>"", EDATE(B28,1), "") -> 46478 | C29: =IF(A29<>"", I28, "") -> 12724.97 | D29: =IF(A29<>"", $M$6, "") -> 659.38366 | E29: 340 | F29: =IF(A29<>"", C29 * ($M$4 / 12), "") -> 148.45799 | G29: =IF(A29<>"", D29 - F29+E29, "") -> 850.92568 | H29: =IF(A29<>"",H28+G29,"") -> 20125.955 | I29: =IF(A29<>"", C29 - G29, "") -> 11874.045 | J29: =IF(A29<>"",Depreciation!F31,"") -> 10284.317
A30: =IF(ROW(A30)-ROW($A$1) <= $M$5, ROW(A30)-ROW($A$1), "") -> 29 | B30: =IF(A30<>"", EDATE(B29,1), "") -> 46508 | C30: =IF(A30<>"", I29, "") -> 11874.045 | D30: =IF(A30<>"", $M$6, "") -> 659.38366 | E30: 340 | F30: =IF(A30<>"", C30 * ($M$4 / 12), "") -> 138.53052 | G30: =IF(A30<>"", D30 - F30+E30, "") -> 860.85314 | H30: =IF(A30<>"",H29+G30,"") -> 20986.809 | I30: =IF(A30<>"", C30 - G30, "") -> 11013.191 | J30: =IF(A30<>"",Depreciation!F32,"") -> 9670.6616
A31: =IF(ROW(A31)-ROW($A$1) <= $M$5, ROW(A31)-ROW($A$1), "") -> 30 | B31: =IF(A31<>"", EDATE(B30,1), "") -> 46539 | C31: =IF(A31<>"", I30, "") -> 11013.191 | D31: =IF(A31<>"", $M$6, "") -> 659.38366 | E31: 340 | F31: =IF(A31<>"", C31 * ($M$4 / 12), "") -> 128.48723 | G31: =IF(A31<>"", D31 - F31+E31, "") -> 870.89643 | H31: =IF(A31<>"",H30+G31,"") -> 21857.705 | I31: =IF(A31<>"", C31 - G31, "") -> 10142.295 | J31: =IF(A31<>"",Depreciation!F33,"") -> 9057.0063
A32: =IF(ROW(A32)-ROW($A$1) <= $M$5, ROW(A32)-ROW($A$1), "") -> 31 | B32: =IF(A32<>"", EDATE(B31,1), "") -> 46569 | C32: =IF(A32<>"", I31, "") -> 10142.295 | D32: =IF(A32<>"", $M$6, "") -> 659.38366 | E32: 340 | F32: =IF(A32<>"", C32 * ($M$4 / 12), "") -> 118.32677 | G32: =IF(A32<>"", D32 - F32+E32, "") -> 881.05689 | H32: =IF(A32<>"",H31+G32,"") -> 22738.762 | I32: =IF(A32<>"", C32 - G32, "") -> 9261.2381 | J32: =IF(A32<>"",Depreciation!F34,"") -> 8443.3509
A33: =IF(ROW(A33)-ROW($A$1) <= $M$5, ROW(A33)-ROW($A$1), "") -> 32 | B33: =IF(A33<>"", EDATE(B32,1), "") -> 46600 | C33: =IF(A33<>"", I32, "") -> 9261.2381 | D33: =IF(A33<>"", $M$6, "") -> 659.38366 | E33: 340 | F33: =IF(A33<>"", C33 * ($M$4 / 12), "") -> 108.04778 | G33: =IF(A33<>"", D33 - F33+E33, "") -> 891.33589 | H33: =IF(A33<>"",H32+G33,"") -> 23630.098 | I33: =IF(A33<>"", C33 - G33, "") -> 8369.9022 | J33: =IF(A33<>"",Depreciation!F35,"") -> 7829.6956
A34: =IF(ROW(A34)-ROW($A$1) <= $M$5, ROW(A34)-ROW($A$1), "") -> 33 | B34: =IF(A34<>"", EDATE(B33,1), "") -> 46631 | C34: =IF(A34<>"", I33, "") -> 8369.9022 | D34: =IF(A34<>"", $M$6, "") -> 659.38366 | F34: =IF(A34<>"", C34 * ($M$4 / 12), "") -> 97.648859 | G34: =IF(A34<>"", D34 - F34+E34, "") -> 561.7348 | H34: =IF(A34<>"",H33+G34,"") -> 24191.833 | I34: =IF(A34<>"", C34 - G34, "") -> 7808.1674 | J34: =IF(A34<>"",Depreciation!F36,"") -> 7216.0403
A35: =IF(ROW(A35)-ROW($A$1) <= $M$5, ROW(A35)-ROW($A$1), "") -> 34 | B35: =IF(A35<>"", EDATE(B34,1), "") -> 46661 | C35: =IF(A35<>"", I34, "") -> 7808.1674 | D35: =IF(A35<>"", $M$6, "") -> 659.38366 | F35: =IF(A35<>"", C35 * ($M$4 / 12), "") -> 91.095286 | G35: =IF(A35<>"", D35 - F35+E35, "") -> 568.28838 | H35: =IF(A35<>"",H34+G35,"") -> 24760.121 | I35: =IF(A35<>"", C35 - G35, "") -> 7239.879 | J35: =IF(A35<>"",Depreciation!F37,"") -> 6602.3849
A36: =IF(ROW(A36)-ROW($A$1) <= $M$5, ROW(A36)-ROW($A$1), "") -> 35 | B36: =IF(A36<>"", EDATE(B35,1), "") -> 46692 | C36: =IF(A36<>"", I35, "") -> 7239.879 | D36: =IF(A36<>"", $M$6, "") -> 659.38366 | F36: =IF(A36<>"", C36 * ($M$4 / 12), "") -> 84.465255 | G36: =IF(A36<>"", D36 - F36+E36, "") -> 574.91841 | H36: =IF(A36<>"",H35+G36,"") -> 25335.039 | I36: =IF(A36<>"", C36 - G36, "") -> 6664.9606 | J36: =IF(A36<>"",Depreciation!F38,"") -> 5988.7296
A37: =IF(ROW(A37)-ROW($A$1) <= $M$5, ROW(A37)-ROW($A$1), "") -> 36 | B37: =IF(A37<>"", EDATE(B36,1), "") -> 46722 | C37: =IF(A37<>"", I36, "") -> 6664.9606 | D37: =IF(A37<>"", $M$6, "") -> 659.38366 | F37: =IF(A37<>"", C37 * ($M$4 / 12), "") -> 77.757873 | G37: =IF(A37<>"", D37 - F37+E37, "") -> 581.62579 | H37: =IF(A37<>"",H36+G37,"") -> 25916.665 | I37: =IF(A37<>"", C37 - G37, "") -> 6083.3348 | J37: =IF(A37<>"",Depreciation!F39,"") -> 5428.4076
A38: =IF(ROW(A38)-ROW($A$1) <= $M$5, ROW(A38)-ROW($A$1), "") -> 37 | B38: =IF(A38<>"", EDATE(B37,1), "") -> 46753 | C38: =IF(A38<>"", I37, "") -> 6083.3348 | D38: =IF(A38<>"", $M$6, "") -> 659.38366 | F38: =IF(A38<>"", C38 * ($M$4 / 12), "") -> 70.972239 | G38: =IF(A38<>"", D38 - F38+E38, "") -> 588.41142 | H38: =IF(A38<>"",H37+G38,"") -> 26505.077 | I38: =IF(A38<>"", C38 - G38, "") -> 5494.9234 | J38: =IF(A38<>"",Depreciation!F40,"") -> 4868.0855
A39: =IF(ROW(A39)-ROW($A$1) <= $M$5, ROW(A39)-ROW($A$1), "") -> 38 | B39: =IF(A39<>"", EDATE(B38,1), "") -> 46784 | C39: =IF(A39<>"", I38, "") -> 5494.9234 | D39: =IF(A39<>"", $M$6, "") -> 659.38366 | F39: =IF(A39<>"", C39 * ($M$4 / 12), "") -> 64.107439 | G39: =IF(A39<>"", D39 - F39+E39, "") -> 595.27622 | H39: =IF(A39<>"",H38+G39,"") -> 27100.353 | I39: =IF(A39<>"", C39 - G39, "") -> 4899.6471 | J39: =IF(A39<>"",Depreciation!F41,"") -> 4307.7635
A40: =IF(ROW(A40)-ROW($A$1) <= $M$5, ROW(A40)-ROW($A$1), "") -> 39 | B40: =IF(A40<>"", EDATE(B39,1), "") -> 46813 | C40: =IF(A40<>"", I39, "") -> 4899.6471 | D40: =IF(A40<>"", $M$6, "") -> 659.38366 | F40: =IF(A40<>"", C40 * ($M$4 / 12), "") -> 57.16255 | G40: =IF(A40<>"", D40 - F40+E40, "") -> 602.22111 | H40: =IF(A40<>"",H39+G40,"") -> 27702.574 | I40: =IF(A40<>"", C40 - G40, "") -> 4297.426 | J40: =IF(A40<>"",Depreciation!F42,"") -> 3747.4415
...

Sheet Charging>Miles
A1: Charge Date | B1: KwH | C1: Estimated Mileage | D1: Wk | F1: KwH to Miles Ratio
A2: 45638 | B2: 68 | C2: 200 | D2: =A2-WEEKDAY(A2,2)+1 -> 45635 | F2: =$C$2/$B$2 -> 2.9411765
A3: 45596 | B3: 40.166 | C3: =B3*$F$2 -> 118.13529 | D3: =A3-WEEKDAY(A3,2)+1 -> 45593
A4: 45595 | B4: 47.252 | C4: =B4*$F$2 -> 138.97647 | D4: =A4-WEEKDAY(A4,2)+1 -> 45593
A5: 45593 | B5: 55.642 | C5: =B5*$F$2 -> 163.65294 | D5: =A5-WEEKDAY(A5,2)+1 -> 45593 | I5: Starting Mileage: | J5: =Outputs!B8 -> 26000
A6: 45592 | B6: 66.192 | C6: =B6*$F$2 -> 194.68235 | D6: =A6-WEEKDAY(A6,2)+1 -> 45586 | F6: Row Labels | G6: Sum of Estimated Mileage | I6: Average Weekly Mileage | J6: =AVERAGE(PivotMileage) -> 589.20464 | M6: Tax Year | N6: $/mile range
A7: 45592 | B7: 12.676 | C7: =B7*$F$2 -> 37.282353 | D7: =A7-WEEKDAY(A7,2)+1 -> 45586 | F7: 45481 | G7: 491.73529 | I7: Mileage Depreciation Factor: | J7: 0.06 | M7: 2020 | N7: 0.575
A8: 45589 | B8: 45.18 | C8: =B8*$F$2 -> 132.88235 | D8: =A8-WEEKDAY(A8,2)+1 -> 45586 | F8: 45488 | G8: 289.61765 | I8: Average Monthly Mileage | J8: =J6*4 -> 2356.8186 | M8: 2021 | N8: 0.56
A9: 45588 | B9: 53.975 | C9: =B9*$F$2 -> 158.75 | D9: =A9-WEEKDAY(A9,2)+1 -> 45586 | F9: 45495 | G9: 372.11765 | I9: Expected Mileage After Year: | M9: 2022-A | N9: 0.585
A10: 45585 | B10: 56.657 | C10: =B10*$F$2 -> 166.63824 | D10: =A10-WEEKDAY(A10,2)+1 -> 45579 | F10: 45502 | G10: 643.11765 | I10: 1 | J10: =J6*52+$J$5 -> 56638.641 | M10: 2022- 2 | N10: 0.625
A11: 45583 | B11: 65.765 | C11: =B11*$F$2 -> 193.42647 | D11: =A11-WEEKDAY(A11,2)+1 -> 45579 | F11: 45509 | G11: 380.05882 | I11: 2 | J11: =$J$6*52+$J10 -> 87277.283 | M11: 2023 | N11: 0.655
A12: 45581 | B12: 47.692 | C12: =B12*$F$2 -> 140.27059 | D12: =A12-WEEKDAY(A12,2)+1 -> 45579 | F12: 45516 | G12: 346.35294 | I12: 2.5 | J12: =$J$6*26+J11 -> 102596.6 | M12: 2024 | N12: 0.67
A13: 45580 | B13: 51.975 | C13: =B13*$F$2 -> 152.86765 | D13: =A13-WEEKDAY(A13,2)+1 -> 45579 | F13: 45537 | G13: 657.23529 | I13: 3 | J13: =$J$6*52+J12 -> 133235.25
A14: 45579 | B14: 56.969 | C14: =B14*$F$2 -> 167.55588 | D14: =A14-WEEKDAY(A14,2)+1 -> 45579 | F14: 45544 | G14: 595.79412
A15: 45576 | B15: 53.526 | C15: =B15*$F$2 -> 157.42941 | D15: =A15-WEEKDAY(A15,2)+1 -> 45572 | F15: 45565 | G15: 327.23235
A16: 45571 | B16: 57.463 | C16: =B16*$F$2 -> 169.00882 | D16: =A16-WEEKDAY(A16,2)+1 -> 45565 | F16: 45572 | G16: 157.42941 | I16: Tax Year | J16: 2024
A17: 45570 | B17: 53.796 | C17: =B17*$F$2 -> 158.22353 | D17: =A17-WEEKDAY(A17,2)+1 -> 45565 | F17: 45579 | G17: 820.75882 | I17: Annual Tax Savings | J17: =(_xlfn.XLOOKUP(J16,M7:M12,N7:N12,"",0,))*J10 -> 37947.89
A18: 45623 | B18: 54.682 | C18: =B18*$F$2 -> 160.82941 | D18: =A18-WEEKDAY(A18,2)+1 -> 45621 | F18: 45586 | G18: 733.24412
A19: 45622 | B19: 11.675 | C19: =B19*$F$2 -> 34.338235 | D19: =A19-WEEKDAY(A19,2)+1 -> 45621 | F19: 45593 | G19: 781.38235
A20: 45617 | B20: 39.854 | C20: =B20*$F$2 -> 117.21765 | D20: =A20-WEEKDAY(A20,2)+1 -> 45614 | F20: 45600 | G20: 493.54118
A21: 45615 | B21: 55.653 | C21: =B21*$F$2 -> 163.68529 | D21: =A21-WEEKDAY(A21,2)+1 -> 45614 | F21: 45607 | G21: 974.66471
A22: 45614 | B22: 51.657 | C22: =B22*$F$2 -> 151.93235 | D22: =A22-WEEKDAY(A22,2)+1 -> 45614 | F22: 45614 | G22: 799.54118
A23: 45613 | B23: 54.921 | C23: =B23*$F$2 -> 161.53235 | D23: =A23-WEEKDAY(A23,2)+1 -> 45607 | F23: 45621 | G23: 576.33529
A24: 45610 | B24: 41.712 | C24: =B24*$F$2 -> 122.68235 | D24: =A24-WEEKDAY(A24,2)+1 -> 45607 | F24: 45628 | G24: 967.22353
A25: 45610 | B25: 54.56 | C25: =B25*$F$2 -> 160.47059 | D25: =A25-WEEKDAY(A25,2)+1 -> 45607 | F25: 45635 | G25: 787.50588
A26: 45608 | B26: 42.926 | C26: =B26*$F$2 -> 126.25294 | D26: =A26-WEEKDAY(A26,2)+1 -> 45607 | F26: 45642 | G26: 250
A27: 45607 | B27: 63.547 | C27: =B27*$F$2 -> 186.90294 | D27: =A27-WEEKDAY(A27,2)+1 -> 45607 | F27: Grand Total | G27: 11444.888
A28: 45604 | B28: 59.228 | C28: =B28*$F$2 -> 174.2 | D28: =A28-WEEKDAY(A28,2)+1 -> 45600
A29: 45600 | B29: 47.886 | C29: =B29*$F$2 -> 140.84118 | D29: =A29-WEEKDAY(A29,2)+1 -> 45600
A30: 45599 | B30: 64.57 | C30: =B30*$F$2 -> 189.91176 | D30: =A30-WEEKDAY(A30,2)+1 -> 45593
A31: 45637 | B31: 68.522 | C31: =B31*$F$2 -> 201.53529 | D31: =A31-WEEKDAY(A31,2)+1 -> 45635
A32: 45636 | B32: 61.16 | C32: =B32*$F$2 -> 179.88235 | D32: =A32-WEEKDAY(A32,2)+1 -> 45635
A33: 45636 | B33: 37.55 | C33: =B33*$F$2 -> 110.44118 | D33: =A33-WEEKDAY(A33,2)+1 -> 45635
A34: 45636 | B34: 0 | C34: =B34*$F$2 -> 0 | D34: =A34-WEEKDAY(A34,2)+1 -> 45635
A35: 45634 | B35: 53.829 | C35: =B35*$F$2 -> 158.32059 | D35: =A35-WEEKDAY(A35,2)+1 -> 45628
A36: 45633 | B36: 38.627 | C36: =B36*$F$2 -> 113.60882 | D36: =A36-WEEKDAY(A36,2)+1 -> 45628
A37: 45631 | B37: 56.87 | C37: =B37*$F$2 -> 167.26471 | D37: =A37-WEEKDAY(A37,2)+1 -> 45628
A38: 45627 | B38: 70.117 | C38: =B38*$F$2 -> 206.22647 | D38: =A38-WEEKDAY(A38,2)+1 -> 45621
A39: 45643 | B39: 85 | C39: =B39*$F$2 -> 250 | D39: =A39-WEEKDAY(A39,2)+1 -> 45642
... A90: 45483 | B90: 40.13 | C90: =B90*$F$2 -> 118.02941 | D90: =A90-WEEKDAY(A90,2)+1 -> 45481

Sheet Hertz
A1: Hertz Fees | B1: Rental | C1: Insurance | D1: Total
A2: Weekly Fee | B2: 300 | C2: 125 | D2: =B2+C2 -> 425
A3: Monthly | B3: =B2*4 -> 1200 | C3: =C2*4 -> 500 | D3: =B3+C3 -> 1700
A4: Yearly | B4: =B3*12 -> 14400 | C4: =C3*12 -> 6000 | D4: =D3*12 -> 20400

Sheet Depreciation
A1: Monthly Depreciation Table | H1: Annual List Range
A2: Month | B2: Annual Factor | C2: Monthly Depreciation Factor (based on 15000 miles) | D2: Trade In Value Before Mileage | E2: Expected Mileage | F2: Value After Mileage Pentalty | H2: A (Months) | I2: B (Years) | J2: C (Depreciation Factor) | K2: Trade In Value
A3: 0 | B3: =IF(A3<=12, $J$4, IF(A3<=24, $J$5, IF(A3<=36, $J$6, IF(A3<=48, $J$7, IF(A3<=60, $J$8, ""))))) -> 0.2 | C3: 0 | D3: =Outputs!B6 -> 32000 | E3: 0 | F3: 0 | H3: 0 | I3: 0 | J3: 0 | K3: =Outputs!B6 -> 32000
A4: 1 | B4: =IF(A4<=12, $J$4, IF(A4<=24, $J$5, IF(A4<=36, $J$6, IF(A4<=48, $J$7, IF(A4<=60, $J$8, ""))))) -> 0.2 | C4: =IF(AND(A4 >= $H$3, A4 < $H$4), ($K$3 - $K$4)/12, IF(AND(A4 >= $H$4, A4 < $H$5), ($K$4 - $K$5)/12, IF(AND(A4 >= $H$5, A4 < $H$6), ($K$5 - $K$6)/12, IF(AND(A4 >= $H$6, A4 < $H$7), ($K$6 - $K$7)/12, IF(AND(A4 >= $H$7, A4 <= $H$8), ($K$7 - $K$8)/12, 0))))) -> 533.33333 | D4: =D3-C4 -> 31466.667 | E4: ='Charging>Miles'!J8 -> 2356.8186 | F4: =D4 - IF('Charging>Miles'!$J$10 > 15000, ('Charging>Miles'!$J$10 - 15000) * 0.1 / 12 * A4, 0) -> 31119.678 | H4: 12 | I4: 1 | J4: 0.2 | K4: =Outputs!$B$6*(1-J4) -> 25600
A5: 2 | B5: =IF(A5<=12, $J$4, IF(A5<=24, $J$5, IF(A5<=36, $J$6, IF(A5<=48, $J$7, IF(A5<=60, $J$8, ""))))) -> 0.2 | C5: =IF(AND(A5 >= $H$3, A5 < $H$4), ($K$3 - $K$4)/12, IF(AND(A5 >= $H$4, A5 < $H$5), ($K$4 - $K$5)/12, IF(AND(A5 >= $H$5, A5 < $H$6), ($K$5 - $K$6)/12, IF(AND(A5 >= $H$6, A5 < $H$7), ($K$6 - $K$7)/12, IF(AND(A5 >= $H$7, A5 <= $H$8), ($K$7 - $K$8)/12, 0))))) -> 533.33333 | D5: =D4-C5 -> 30933.333 | E5: =$E$4+E4 -> 4713.6372 | F5: =D5 - IF('Charging>Miles'!$J$10 > 15000, ('Charging>Miles'!$J$10 - 15000) * 0.1 / 12 * A5, 0) -> 30239.356 | H5: 24 | I5: 2 | J5: 0.35 | K5: =Outputs!$B$6*(1-J5) -> 20800
A6: 3 | B6: =IF(A6<=12, $J$4, IF(A6<=24, $J$5, IF(A6<=36, $J$6, IF(A6<=48, $J$7, IF(A6<=60, $J$8, ""))))) -> 0.2 | C6: =IF(AND(A6 >= $H$3, A6 < $H$4), ($K$3 - $K$4)/12, IF(AND(A6 >= $H$4, A6 < $H$5), ($K$4 - $K$5)/12, IF(AND(A6 >= $H$5, A6 < $H$6), ($K$5 - $K$6)/12, IF(AND(A6 >= $H$6, A6 < $H$7), ($K$6 - $K$7)/12, IF(AND(A6 >= $H$7, A6 <= $H$8), ($K$7 - $K$8)/12, 0))))) -> 533.33333 | D6: =D5-C6 -> 30400 | E6: =$E$4+E5 -> 7070.4557 | F6: =D6 - IF('Charging>Miles'!$J$10 > 15000, ('Charging>Miles'!$J$10 - 15000) * 0.1 / 12 * A6, 0) -> 29359.034 | H6: 36 | I6: 3 | J6: 0.45 | K6: =Outputs!$B$6*(1-J6) -> 17600
A7: 4 | B7: =IF(A7<=12, $J$4, IF(A7<=24, $J$5, IF(A7<=36, $J$6, IF(A7<=48, $J$7, IF(A7<=60, $J$8, ""))))) -> 0.2 | C7: =IF(AND(A7 >= $H$3, A7 < $H$4), ($K$3 - $K$4)/12, IF(AND(A7 >= $H$4, A7 < $H$5), ($K$4 - $K$5)/12, IF(AND(A7 >= $H$5, A7 < $H$6), ($K$5 - $K$6)/12, IF(AND(A7 >= $H$6, A7 < $H$7), ($K$6 - $K$7)/12, IF(AND(A7 >= $H$7, A7 <= $H$8), ($K$7 - $K$8)/12, 0))))) -> 533.33333 | D7: =D6-C7 -> 29866.667 | E7: =$E$4+E6 -> 9427.2743 | F7: =D7 - IF('Charging>Miles'!$J$10 > 15000, ('Charging>Miles'!$J$10 - 15000) * 0.1 / 12 * A7, 0) -> 28478.712 | H7: 48 | I7: 4 | J7: 0.53 | K7: =Outputs!$B$6*(1-J7) -> 15040
A8: 5 | B8: =IF(A8<=12, $J$4, IF(A8<=24, $J$5, IF(A8<=36, $J$6, IF(A8<=48, $J$7, IF(A8<=60, $J$8, ""))))) -> 0.2 | C8: =IF(AND(A8 >= $H$3, A8 < $H$4), ($K$3 - $K$4)/12, IF(AND(A8 >= $H$4, A8 < $H$5), ($K$4 - $K$5)/12, IF(AND(A8 >= $H$5, A8 < $H$6), ($K$5 - $K$6)/12, IF(AND(A8 >= $H$6, A8 < $H$7), ($K$6 - $K$7)/12, IF(AND(A8 >= $H$7, A8 <= $H$8), ($K$7 - $K$8)/12, 0))))) -> 533.33333 | D8: =D7-C8 -> 29333.333 | E8: =$E$4+E7 -> 11784.093 | F8: =D8 - IF('Charging>Miles'!$J$10 > 15000, ('Charging>Miles'!$J$10 - 15000) * 0.1 / 12 * A8, 0) -> 27598.39 | H8: 60 | I8: 5 | J8: 0.58 | K8: =Outputs!$B$6*(1-J8) -> 13440
A9: 6 | B9: =IF(A9<=12, $J$4, IF(A9<=24, $J$5, IF(A9<=36, $J$6, IF(A9<=48, $J$7, IF(A9<=60, $J$8, ""))))) -> 0.2 | C9: =IF(AND(A9 >= $H$3, A9 < $H$4), ($K$3 - $K$4)/12, IF(AND(A9 >= $H$4, A9 < $H$5), ($K$4 - $K$5)/12, IF(AND(A9 >= $H$5, A9 < $H$6), ($K$5 - $K$6)/12, IF(AND(A9 >= $H$6, A9 < $H$7), ($K$6 - $K$7)/12, IF(AND(A9 >= $H$7, A9 <= $H$8), ($K$7 - $K$8)/12, 0))))) -> 533.33333 | D9: =D8-C9 -> 28800 | E9: =$E$4+E8 -> 14140.911 | F9: =D9 - IF('Charging>Miles'!$J$10 > 15000, ('Charging>Miles'!$J$10 - 15000) * 0.1 / 12 * A9, 0) -> 26718.068
A10: 7 | B10: =IF(A10<=12, $J$4, IF(A10<=24, $J$5, IF(A10<=36, $J$6, IF(A10<=48, $J$7, IF(A10<=60, $J$8, ""))))) -> 0.2 | C10: =IF(AND(A10 >= $H$3, A10 < $H$4), ($K$3 - $K$4)/12, IF(AND(A10 >= $H$4, A10 < $H$5), ($K$4 - $K$5)/12, IF(AND(A10 >= $H$5, A10 < $H$6), ($K$5 - $K$6)/12, IF(AND(A10 >= $H$6, A10 < $H$7), ($K$6 - $K$7)/12, IF(AND(A10 >= $H$7, A10 <= $H$8), ($K$7 - $K$8)/12, 0))))) -> 533.33333 | D10: =D9-C10 -> 28266.667 | E10: =$E$4+E9 -> 16497.73 | F10: =D10 - IF('Charging>Miles'!$J$10 > 15000, ('Charging>Miles'!$J$10 - 15000) * 0.1 / 12 * A10, 0) -> 25837.746
A11: 8 | B11: =IF(A11<=12, $J$4, IF(A11<=24, $J$5, IF(A11<=36, $J$6, IF(A11<=48, $J$7, IF(A11<=60, $J$8, ""))))) -> 0.2 | C11: =IF(AND(A11 >= $H$3, A11 < $H$4), ($K$3 - $K$4)/12, IF(AND(A11 >= $H$4, A11 < $H$5), ($K$4 - $K$5)/12, IF(AND(A11 >= $H$5, A11 < $H$6), ($K$5 - $K$6)/12, IF(AND(A11 >= $H$6, A11 < $H$7), ($K$6 - $K$7)/12, IF(AND(A11 >= $H$7, A11 <= $H$8), ($K$7 - $K$8)/12, 0))))) -> 533.33333 | D11: =D10-C11 -> 27733.333 | E11: =$E$4+E10 -> 18854.549 | F11: =D11 - IF('Charging>Miles'!$J$10 > 15000, ('Charging>Miles'!$J$10 - 15000) * 0.1 / 12 * A11, 0) -> 24957.424
A12: 9 | B12: =IF(A12<=12, $J$4, IF(A12<=24, $J$5, IF(A12<=36, $J$6, IF(A12<=48, $J$7, IF(A12<=60, $J$8, ""))))) -> 0.2 | C12: =IF(AND(A12 >= $H$3, A12 < $H$4), ($K$3 - $K$4)/12, IF(AND(A12 >= $H$4, A12 < $H$5), ($K$4 - $K$5)/12, IF(AND(A12 >= $H$5, A12 < $H$6), ($K$5 - $K$6)/12, IF(AND(A12 >= $H$6, A12 < $H$7), ($K$6 - $K$7)/12, IF(AND(A12 >= $H$7, A12 <= $H$8), ($K$7 - $K$8)/12, 0))))) -> 533.33333 | D12: =D11-C12 -> 27200 | E12: =$E$4+E11 -> 21211.367 | F12: =D12 - IF('Charging>Miles'!$J$10 > 15000, ('Charging>Miles'!$J$10 - 15000) * 0.1 / 12 * A12, 0) -> 24077.102
A13: 10 | B13: =IF(A13<=12, $J$4, IF(A13<=24, $J$5, IF(A13<=36, $J$6, IF(A13<=48, $J$7, IF(A13<=60, $J$8, ""))))) -> 0.2 | C13: =IF(AND(A13 >= $H$3, A13 < $H$4), ($K$3 - $K$4)/12, IF(AND(A13 >= $H$4, A13 < $H$5), ($K$4 - $K$5)/12, IF(AND(A13 >= $H$5, A13 < $H$6), ($K$5 - $K$6)/12, IF(AND(A13 >= $H$6, A13 < $H$7), ($K$6 - $K$7)/12, IF(AND(A13 >= $H$7, A13 <= $H$8), ($K$7 - $K$8)/12, 0))))) -> 533.33333 | D13: =D12-C13 -> 26666.667 | E13: =$E$4+E12 -> 23568.186 | F13: =D13 - IF('Charging>Miles'!$J$10 > 15000, ('Charging>Miles'!$J$10 - 15000) * 0.1 / 12 * A13, 0) -> 23196.78
A14: 11 | B14: =IF(A14<=12, $J$4, IF(A14<=24, $J$5, IF(A14<=36, $J$6, IF(A14<=48, $J$7, IF(A14<=60, $J$8, ""))))) -> 0.2 | C14: =IF(AND(A14 >= $H$3, A14 < $H$4), ($K$3 - $K$4)/12, IF(AND(A14 >= $H$4, A14 < $H$5), ($K$4 - $K$5)/12, IF(AND(A14 >= $H$5, A14 < $H$6), ($K$5 - $K$6)/12, IF(AND(A14 >= $H$6, A14 < $H$7), ($K$6 - $K$7)/12, IF(AND(A14 >= $H$7, A14 <= $H$8), ($K$7 - $K$8)/12, 0))))) -> 533.33333 | D14: =D13-C14 -> 26133.333 | E14: =$E$4+E13 -> 25925.004 | F14: =D14 - IF('Charging>Miles'!$J$10 > 15000, ('Charging>Miles'!$J$10 - 15000) * 0.1 / 12 * A14, 0) -> 22316.458
A15: 12 | B15: =IF(A15<=12, $J$4, IF(A15<=24, $J$5, IF(A15<=36, $J$6, IF(A15<=48, $J$7, IF(A15<=60, $J$8, ""))))) -> 0.2 | C15: =IF(AND(A15 >= $H$3, A15 < $H$4), ($K$3 - $K$4)/12, IF(AND(A15 >= $H$4, A15 < $H$5), ($K$4 - $K$5)/12, IF(AND(A15 >= $H$5, A15 < $H$6), ($K$5 - $K$6)/12, IF(AND(A15 >= $H$6, A15 < $H$7), ($K$6 - $K$7)/12, IF(AND(A15 >= $H$7, A15 <= $H$8), ($K$7 - $K$8)/12, 0))))) -> 400 | D15: =D14-C15 -> 25733.333 | E15: =$E$4+E14 -> 28281.823 | F15: =D15 - IF('Charging>Miles'!$J$10 > 15000, ('Charging>Miles'!$J$10 - 15000) * 0.1 / 12 * A15, 0) -> 21569.469
A16: 13 | B16: =IF(A16<=12, $J$4, IF(A16<=24, $J$5, IF(A16<=36, $J$6, IF(A16<=48, $J$7, IF(A16<=60, $J$8, ""))))) -> 0.35 | C16: =IF(AND(A16 >= $H$3, A16 < $H$4), ($K$3 - $K$4)/12, IF(AND(A16 >= $H$4, A16 < $H$5), ($K$4 - $K$5)/12, IF(AND(A16 >= $H$5, A16 < $H$6), ($K$5 - $K$6)/12, IF(AND(A16 >= $H$6, A16 < $H$7), ($K$6 - $K$7)/12, IF(AND(A16 >= $H$7, A16 <= $H$8), ($K$7 - $K$8)/12, 0))))) -> 400 | D16: =D15-C16 -> 25333.333 | E16: =$E$4+E15 -> 30638.641 | F16: =D16 - IF('Charging>Miles'!$J$10 > 15000, ('Charging>Miles'!$J$10 - 15000) * 0.1 / 12 * A16, 0) -> 20822.481
A17: 14 | B17: =IF(A17<=12, $J$4, IF(A17<=24, $J$5, IF(A17<=36, $J$6, IF(A17<=48, $J$7, IF(A17<=60, $J$8, ""))))) -> 0.35 | C17: =IF(AND(A17 >= $H$3, A17 < $H$4), ($K$3 - $K$4)/12, IF(AND(A17 >= $H$4, A17 < $H$5), ($K$4 - $K$5)/12, IF(AND(A17 >= $H$5, A17 < $H$6), ($K$5 - $K$6)/12, IF(AND(A17 >= $H$6, A17 < $H$7), ($K$6 - $K$7)/12, IF(AND(A17 >= $H$7, A17 <= $H$8), ($K$7 - $K$8)/12, 0))))) -> 400 | D17: =D16-C17 -> 24933.333 | E17: =$E$4+E16 -> 32995.46 | F17: =D17 - IF('Charging>Miles'!$J$10 > 15000, ('Charging>Miles'!$J$10 - 15000) * 0.1 / 12 * A17, 0) -> 20075.492
A18: 15 | B18: =IF(A18<=12, $J$4, IF(A18<=24, $J$5, IF(A18<=36, $J$6, IF(A18<=48, $J$7, IF(A18<=60, $J$8, ""))))) -> 0.35 | C18: =IF(AND(A18 >= $H$3, A18 < $H$4), ($K$3 - $K$4)/12, IF(AND(A18 >= $H$4, A18 < $H$5), ($K$4 - $K$5)/12, IF(AND(A18 >= $H$5, A18 < $H$6), ($K$5 - $K$6)/12, IF(AND(A18 >= $H$6, A18 < $H$7), ($K$6 - $K$7)/12, IF(AND(A18 >= $H$7, A18 <= $H$8), ($K$7 - $K$8)/12, 0))))) -> 400 | D18: =D17-C18 -> 24533.333 | E18: =$E$4+E17 -> 35352.279 | F18: =D18 - IF('Charging>Miles'!$J$10 > 15000, ('Charging>Miles'!$J$10 - 15000) * 0.1 / 12 * A18, 0) -> 19328.503
A19: 16 | B19: =IF(A19<=12, $J$4, IF(A19<=24, $J$5, IF(A19<=36, $J$6, IF(A19<=48, $J$7, IF(A19<=60, $J$8, ""))))) -> 0.35 | C19: =IF(AND(A19 >= $H$3, A19 < $H$4), ($K$3 - $K$4)/12, IF(AND(A19 >= $H$4, A19 < $H$5), ($K$4 - $K$5)/12, IF(AND(A19 >= $H$5, A19 < $H$6), ($K$5 - $K$6)/12, IF(AND(A19 >= $H$6, A19 < $H$7), ($K$6 - $K$7)/12, IF(AND(A19 >= $H$7, A19 <= $H$8), ($K$7 - $K$8)/12, 0))))) -> 400 | D19: =D18-C19 -> 24133.333 | E19: =$E$4+E18 -> 37709.097 | F19: =D19 - IF('Charging>Miles'!$J$10 > 15000, ('Charging>Miles'!$J$10 - 15000) * 0.1 / 12 * A19, 0) -> 18581.514
A20: 17 | B20: =IF(A20<=12, $J$4, IF(A20<=24, $J$5, IF(A20<=36, $J$6, IF(A20<=48, $J$7, IF(A20<=60, $J$8, ""))))) -> 0.35 | C20: =IF(AND(A20 >= $H$3, A20 < $H$4), ($K$3 - $K$4)/12, IF(AND(A20 >= $H$4, A20 < $H$5), ($K$4 - $K$5)/12, IF(AND(A20 >= $H$5, A20 < $H$6), ($K$5 - $K$6)/12, IF(AND(A20 >= $H$6, A20 < $H$7), ($K$6 - $K$7)/12, IF(AND(A20 >= $H$7, A20 <= $H$8), ($K$7 - $K$8)/12, 0))))) -> 400 | D20: =D19-C20 -> 23733.333 | E20: =$E$4+E19 -> 40065.916 | F20: =D20 - IF('Charging>Miles'!$J$10 > 15000, ('Charging>Miles'!$J$10 - 15000) * 0.1 / 12 * A20, 0) -> 17834.526
... A63: 60 | B63: =IF(A63<=12, $J$4, IF(A63<=24, $J$5, IF(A63<=36, $J$6, IF(A63<=48, $J$7, IF(A63<=60, $J$8, ""))))) -> 0.58 | C63: =IF(AND(A63 >= $H$3, A63 < $H$4), ($K$3 - $K$4)/12, IF(AND(A63 >= $H$4, A63 < $H$5), ($K$4 - $K$5)/12, IF(AND(A63 >= $H$5, A63 < $H$6), ($K$5 - $K$6)/12, IF(AND(A63 >= $H$6, A63 < $H$7), ($K$6 - $K$7)/12, IF(AND(A63 >= $H$7, A63 <= $H$8), ($K$7 - $K$8)/12, 0))))) -> 133.33333 | D63: =D62-C63 -> 13840 | E63: =$E$4+E62 -> 141409.11 | F63: =D63 - IF('Charging>Miles'!$J$10 > 15000, ('Charging>Miles'!$J$10 - 15000) * 0.1 / 12 * A63, 0) -> -6979.3207

Sheet Earnings&Savings
K1: Reserves
K2: 2000
